<?xml version="1.0"?>
<robot name="PA10c"
		 xmlns:xacro="http://www.ros.org/wiki/xacro"
		 xmlns:sensor="http://playerstage.sourceforge.net/gazebo/xmlschema/#sensor"
		 xmlns:controller="http://playerstage.sourceforge.net/gazebo/xmlschema/#controller"
       xmlns:interface="http://playerstage.sourceforge.net/gazebo/xmlschema/#interface">

  <xacro:include filename="$(find agni_description)/urdf/util.urdf.xacro"/>

  <macro name="pa10c_arm" params="name">
  <link name="${name}arm_base_link">
    <visual>
      <origin xyz="0 0 0" rpy="0 0 0"/>
      <geometry>
        <mesh filename="package://agni_description/pa10/meshes/pa-7c/link0_mesh.dae" scale="1 1 1" />
      </geometry>
    </visual>
    <collision>
      <origin xyz="0 0 0.100" rpy="0 0 0"/>
      <geometry>
        <cylinder length="0.200" radius="0.115"/>
      </geometry>
    </collision>
    <collision>
      <origin xyz="0 0.130 0.090" rpy="0 0 0"/>
      <geometry>
        <box size="0.160 0.080 0.160" />
      </geometry>
    </collision>
    <inertial>
      <mass value="6.88" />
      <origin xyz="0 0 0.091" rpy="0 0 0"/>
      <inertia ixx="0.043" ixy="0" ixz="0" iyy="0.043" iyz="0" izz="0.0416"/>
    </inertial>
  </link>
  <link name="${name}arm_1_link">
    <visual>
      <origin xyz="0 0 0" rpy="0 0 0"/>
      <geometry>
        <mesh filename="package://agni_description/pa10/meshes/pa-7c/link1_mesh.dae" scale="1 1 1" />
      </geometry>
    </visual>
    <collision>
      <origin xyz="0 0 0.210" rpy="0 0 0"/>
      <geometry>
        <cylinder length="0.020" radius="0.110"/>
      </geometry>
    </collision>
    <collision>
      <origin xyz="0.0 0.105 0.3" rpy="0 0 0"/>
      <geometry>
		  <box size="0.140 0.05 0.180" />
      </geometry>
    </collision>
    <collision>
      <origin xyz="0.0 -0.105 0.3" rpy="0 0 0"/>
      <geometry>
		  <box size="0.140 0.05 0.180" />
      </geometry>
    </collision>
    <inertial>
      <mass value="7.33" />
      <origin xyz="0 0 0.160" rpy="0 0 0"/>
      <inertia ixx="0.11" ixy="0" ixz="0" iyy="0.11" iyz="0" izz="0.037"/>
    </inertial>
  </link>
  <link name="${name}arm_2_link">
    <visual>
      <origin xyz="0 0 -0.317" rpy="0 0 0"/>
      <geometry>
        <mesh filename="package://agni_description/pa10/meshes/pa-7c/link2_mesh.dae" scale="1 1 1" />
      </geometry>
    </visual>
    <collision>
      <origin xyz="0 0 0.183" rpy="0 0 0"/>
      <geometry>
        <cylinder length="0.266" radius="0.07"/>
      </geometry>
    </collision>
    <collision>
      <origin xyz="0 0 0.0" rpy="1.5708 0 0"/>
      <geometry>
        <cylinder length="0.160" radius="0.075"/>
      </geometry>
    </collision>
    <inertial>
      <mass value="10.76" />
      <origin xyz="0 0 0.063" rpy="0 0 0"/>
      <inertia ixx="0.168" ixy="0" ixz="0" iyy="0.168" iyz="0" izz="0.026"/>
    </inertial>
  </link>
  <link name="${name}arm_3_link">
    <visual>
      <origin xyz="0 0 -0.317" rpy="0 0 0"/>
      <geometry>
        <mesh filename="package://agni_description/pa10/meshes/pa-7c/link3_mesh.dae" scale="1 1 1" />
      </geometry>
    </visual>
    <collision>
      <origin xyz="0 0 0.333" rpy="0 0 0"/>
      <geometry>
         <box size="0.120 0.116 0.034" />
      </geometry>
    </collision>
    <collision>
      <origin xyz="0.0 0.083 0.413" rpy="0 0 0"/>
      <geometry>
		  <box size="0.120 0.05 0.20" />
      </geometry>
    </collision>
    <collision>
      <origin xyz="0.0 -0.083 0.413" rpy="0 0 0"/>
      <geometry>
		  <box size="0.120 0.05 0.20" />
      </geometry>
    </collision>
    <inertial>
      <mass value="2.97" />
      <origin xyz="0 0 0.346" rpy="0 0 0"/>
      <inertia ixx="0.028" ixy="0" ixz="0" iyy="0.028" iyz="0" izz="0.073"/>
    </inertial>
  </link>
  <link name="${name}arm_4_link">
    <visual>
      <origin xyz="0 0 -0.767" rpy="0 0 0"/>
      <geometry>
        <mesh filename="package://agni_description/pa10/meshes/pa-7c/link4_mesh.dae" scale="1 1 1" />
      </geometry>
    </visual>
    <collision>
      <origin xyz="0 0 0.170" rpy="0 0 0"/>
      <geometry>
        <cylinder length="0.248" radius="0.055"/>
      </geometry>
    </collision>
    <collision>
      <origin xyz="0 0 0.0" rpy="1.5708 0 0"/>
      <geometry>
        <cylinder length="0.116" radius="0.055"/>
      </geometry>
    </collision>
    <inertial>
      <mass value="4.86" />
      <origin xyz="0 0 0.0485" rpy="0 0 0"/>
      <inertia ixx="0.0055" ixy="0" ixz="0" iyy="0.0055" iyz="0" izz="0.0073"/>
    </inertial>
  </link>
  <link name="${name}arm_5_link">
    <visual>
      <origin xyz="0 0 -0.767" rpy="0 0 0"/>
      <geometry>
        <mesh filename="package://agni_description/pa10/meshes/pa-7c/link5_mesh.dae" scale="1 1 1" />
      </geometry>
    </visual>
    <collision>
      <origin xyz="0 0 0.322" rpy="0 0 0"/>
      <geometry>
         <box size="0.09 0.102 0.070" />
      </geometry>
    </collision>
    <collision>
      <origin xyz="0.0 0.066 0.403" rpy="0 0 0"/>
      <geometry>
		  <box size="0.09 0.03 0.242" />
      </geometry>
    </collision>
    <collision>
      <origin xyz="0.0 -0.066 0.403" rpy="0 0 0"/>
      <geometry>
		  <box size="0.09 0.03 0.242" />
      </geometry>
    </collision>
    <inertial>
      <mass value="3.08" />
      <origin xyz="0 0 0.368" rpy="0 0 0"/>
      <inertia ixx="0.02" ixy="0" ixz="0" iyy="0.02" iyz="0" izz="0.0046"/>
    </inertial>
  </link>
  <link name="${name}arm_6_link">
    <visual>
      <origin xyz="0 0 -1.247" rpy="0 0 0"/>
      <geometry>
        <mesh filename="package://agni_description/pa10/meshes/pa-7c/link6_mesh.dae" scale="1 1 1" />
      </geometry>
    </visual>
    <collision>
      <origin xyz="0 0 -0.023" rpy="0 0 0"/>
      <geometry>
        <cylinder length="0.186" radius="0.05"/>
      </geometry>
    </collision>
    <inertial>
      <mass value="3.00" />
      <origin xyz="0 0 -0.042" rpy="0 0 0"/>
      <inertia ixx="0.011" ixy="0" ixz="0" iyy="0.011" iyz="0" izz="0.0038"/>
    </inertial>
  </link>
  <link name="${name}arm_7_link">
    <visual>
      <origin xyz="0 0 0" rpy="0 0 0"/>
      <geometry>
        <mesh filename="package://agni_description/pa10/meshes/pa-7c/link7_mesh.dae" scale="1 1 1" />
      </geometry>
    </visual>
    <collision>
      <origin xyz="0 0 -0.01" rpy="0 0 0"/>
      <geometry>
        <cylinder length="0.02" radius="0.04"/>
      </geometry>
    </collision>
    <inertial>
      <mass value="0.12" />
      <origin xyz="0 0 -0.048" rpy="0 0 0"/>
      <inertia ixx="0.000052" ixy="0.0" ixz="0" iyy="0.000052" iyz="0" izz="0.000096"/>
    </inertial>
  </link>

  <joint name="${name}S1" type="revolute">
    <parent link="${name}arm_base_link"/>
    <child  link="${name}arm_1_link"/>
    <origin xyz="0 0 0" rpy="0 0 0 "/>
    <axis   xyz="0 0 1"/>
    <limit lower="${-177/180*M_PI}" upper="${177/180*M_PI}" effort="100" velocity="1" />
    <dynamics damping="0.2" friction="0" />
  </joint>
  <joint name="${name}S2" type="revolute">
    <parent link="${name}arm_1_link"/>
    <child  link="${name}arm_2_link"/>
    <origin xyz="0 0 0.317" rpy="0 0 0 "/>
    <axis   xyz="0 1 0"/>
    <limit lower="${-94/180*M_PI}" upper="${+94/180*M_PI}" effort="100" velocity="1" />
    <dynamics damping="0.2" friction="0" />
  </joint>
  <joint name="${name}S3" type="revolute">
    <parent link="${name}arm_2_link"/>
    <child  link="${name}arm_3_link"/>
    <origin xyz="0 0 0" rpy="0 0 0 "/>
    <axis   xyz="0 0 1"/>
    <limit lower="${-174/180*M_PI}" upper="${174/180*M_PI}" effort="100" velocity="2" />
    <dynamics damping="0.2" friction="0" />
  </joint>
  <joint name="${name}E1" type="revolute">
    <parent link="${name}arm_3_link"/>
    <child  link="${name}arm_4_link"/>
    <origin xyz="0 0 0.45" rpy="0 0 0 "/>
    <axis   xyz="0 1 0"/>
    <limit lower="${-137/180*M_PI}" upper="${137/180*M_PI}" effort="100" velocity="2" />
    <dynamics damping="0.2" friction="0" />
  </joint>
  <joint name="${name}E2" type="revolute">
    <parent link="${name}arm_4_link"/>
    <child  link="${name}arm_5_link"/>
    <origin xyz="0 0 0" rpy="0 0 0 "/>
    <axis   xyz="0 0 1"/>
    <limit lower="${-255/180*M_PI}" upper="${255/180*M_PI}" effort="100" velocity="6.28" />
    <dynamics damping="0.2" friction="0" />
  </joint>
  <joint name="${name}W1" type="revolute">
    <parent link="${name}arm_5_link"/>
    <child  link="${name}arm_6_link"/>
    <origin xyz="0 0 0.480" rpy="0 0 0 "/>
    <axis   xyz="0 1 0"/>
    <limit lower="${-165/180*M_PI}" upper="${165/180*M_PI}" effort="100" velocity="6.28" />
    <dynamics damping="0.2" friction="0" />
  </joint>
  <joint name="${name}W2" type="revolute">
    <parent link="${name}arm_6_link"/>
    <child  link="${name}arm_7_link"/>
    <origin xyz="0 0 0.07" rpy="0 0 0 "/>
    <axis   xyz="0 0 1"/>
    <limit lower="${-255/180*M_PI}" upper="${255/180*M_PI}" effort="100" velocity="6.28" />
    <dynamics damping="0.2" friction="0" />
  </joint>

  <joint name="${name}arm_hand_fixed_joint" type="fixed">
	 <parent link="${name}arm_7_link"/>
	 <child link="${name}arm_hand_mount"/>
  </joint>
  
  <link name="${name}arm_hand_mount" />
  </macro>
</robot>
