<robot xmlns:xacro="http://ros.org/wiki/xacro"
		 xmlns:sensor="http://playerstage.sourceforge.net/gazebo/xmlschema/#sensor"
       xmlns:controller="http://playerstage.sourceforge.net/gazebo/xmlschema/#controller"
       xmlns:joint="http://playerstage.sourceforge.net/gazebo/xmlschema/#slider"
       xmlns:interface="http://playerstage.sourceforge.net/gazebo/xmlschema/#interface"
       xmlns:body="http://playerstage.sourceforge.net/gazebo/xmlschema/#body"
       xmlns:geom="http://playerstage.sourceforge.net/gazebo/xmlschema/#geom">

  <xacro:macro name="palm" params="prefix='${prefix}' right='${right}'">
    <link name="${prefix}palm">
      <inertial>
		  <origin xyz="0 0 0.035" rpy="0 0 0" />
		  <mass value="0.3" />
		  <inertia  ixx="0.5" ixy="0.0"  ixz="0.0"  iyy="0.5"  iyz="0.0"	izz="0.3" />
      </inertial>

      <visual>
		  <origin xyz="0 0 0" rpy="0 0 0" />
		  <geometry name="palm">
			 <mesh filename="package://agni_description/shadow/meshes/palm.dae" 
					 scale="${right*0.001} 0.001 0.001" />
		  </geometry>
		  <material name="Grey"/>
      </visual>

      <collision>
		  <if value="${right+1}"><origin xyz="0.005 0 0.035" rpy="0 0 0" /></if>
		  <if value="${right+1}"><origin xyz="0.005 0 0.035" rpy="0 0 0" /></if>
		  <geometry name="palm">
			 <box size="0.05 0.02 0.07" />
		  </geometry>
      </collision>
    </link>

    <joint name="${prefix}WRJ1" type="revolute">
      <parent link="right_hand_wrist"/>
      <child link="${prefix}palm"/>
      <origin xyz="0 0 0.034" rpy="0 0 0" />
      <axis xyz="1 0 0" />
      <limit lower="${-45/180*M_PI}" upper="${30/180*M_PI}"
      effort="5" velocity="1.0"/>
      <dynamics damping="100.5"/>
    </joint>

  </xacro:macro>

</robot>
